WARNING:passlib.handlers.bcrypt:(trapped) error reading bcrypt version
Traceback (most recent call last):
  File "C:\Users\hugogarsan\AppData\Local\Packages\PythonSoftwareFoundation.Python.3.11_qbz5n2kfra8p0\LocalCache\local-packages\Python311\site-packages\passlib\handlers\bcrypt.py", line 620, in _load_backend_mixin
    version = _bcrypt.__about__.__version__
              ^^^^^^^^^^^^^^^^^
AttributeError: module 'bcrypt' has no attribute '__about__'
INFO:root:2024-04-10 19:07:12.369192 - Inicio de sesión exitoso para usuario: string
INFO:root:2024-04-10 19:07:49.331665 - Inicio de sesión exitoso para usuario: string
WARNING:passlib.handlers.bcrypt:(trapped) error reading bcrypt version
Traceback (most recent call last):
  File "C:\Users\hugogarsan\AppData\Local\Packages\PythonSoftwareFoundation.Python.3.11_qbz5n2kfra8p0\LocalCache\local-packages\Python311\site-packages\passlib\handlers\bcrypt.py", line 620, in _load_backend_mixin
    version = _bcrypt.__about__.__version__
              ^^^^^^^^^^^^^^^^^
AttributeError: module 'bcrypt' has no attribute '__about__'
INFO:root:2024-04-11 18:18:35.898722 - Inicio de sesión exitoso para usuario: string
WARNING:passlib.handlers.bcrypt:(trapped) error reading bcrypt version
Traceback (most recent call last):
  File "C:\Users\hugogarsan\AppData\Local\Packages\PythonSoftwareFoundation.Python.3.11_qbz5n2kfra8p0\LocalCache\local-packages\Python311\site-packages\passlib\handlers\bcrypt.py", line 620, in _load_backend_mixin
    version = _bcrypt.__about__.__version__
              ^^^^^^^^^^^^^^^^^
AttributeError: module 'bcrypt' has no attribute '__about__'
WARNING:passlib.handlers.bcrypt:(trapped) error reading bcrypt version
Traceback (most recent call last):
  File "C:\Users\hugogarsan\AppData\Local\Packages\PythonSoftwareFoundation.Python.3.11_qbz5n2kfra8p0\LocalCache\local-packages\Python311\site-packages\passlib\handlers\bcrypt.py", line 620, in _load_backend_mixin
    version = _bcrypt.__about__.__version__
              ^^^^^^^^^^^^^^^^^
AttributeError: module 'bcrypt' has no attribute '__about__'
INFO:root:2024-04-12 17:33:45.808071 - Intento de inicio de sesión fallido para usuario: hugog
INFO:root:2024-04-12 17:42:53.102527 - Intento de inicio de sesión fallido para usuario: antonieta
INFO:root:2024-04-12 17:43:11.017880 - Intento de inicio de sesión fallido para usuario: hugog
INFO:root:2024-04-12 17:43:16.660494 - Intento de inicio de sesión fallido para usuario: hugogarsan
INFO:root:2024-04-12 17:46:53.905810 - Intento de inicio de sesión fallido para usuario: hugog
INFO:root:2024-04-12 17:47:03.915731 - Intento de inicio de sesión fallido para usuario: hugog
INFO:root:2024-04-12 17:53:06.063233 - Intento de inicio de sesión fallido para usuario: hugogarsan
INFO:root:2024-04-12 18:12:26.853995 - Intento de inicio de sesión fallido para usuario: 
INFO:root:2024-04-12 18:43:41.795474 - Intento de inicio de sesión fallido para usuario: hugog
INFO:root:2024-04-12 18:47:23.391692 - Intento de inicio de sesión fallido para usuario: hugofasfa
INFO:root:2024-04-12 18:47:35.486190 - Intento de inicio de sesión fallido para usuario: hugog
INFO:root:2024-04-12 18:47:40.654913 - Intento de inicio de sesión fallido para usuario: hugogarsan
INFO:root:2024-04-12 18:48:16.107970 - Intento de inicio de sesión fallido para usuario: String
INFO:root:2024-04-12 18:52:02.855257 - Intento de inicio de sesión fallido para usuario: String
INFO:root:2024-04-12 18:52:14.273495 - Intento de inicio de sesión fallido para usuario: hugog
INFO:root:2024-04-12 18:52:21.463118 - Intento de inicio de sesión fallido para usuario: hugog
WARNING:passlib.handlers.bcrypt:(trapped) error reading bcrypt version
Traceback (most recent call last):
  File "C:\Users\hugogarsan\AppData\Local\Packages\PythonSoftwareFoundation.Python.3.11_qbz5n2kfra8p0\LocalCache\local-packages\Python311\site-packages\passlib\handlers\bcrypt.py", line 620, in _load_backend_mixin
    version = _bcrypt.__about__.__version__
              ^^^^^^^^^^^^^^^^^
AttributeError: module 'bcrypt' has no attribute '__about__'
INFO:root:2024-04-12 18:53:28.777161 - Intento de inicio de sesión fallido para usuario: hugo123
INFO:root:2024-04-12 18:53:49.295655 - Intento de inicio de sesión fallido para usuario: hugo123
INFO:root:2024-04-12 19:01:30.306207 - Intento de inicio de sesión fallido para usuario: hugo123
WARNING:passlib.handlers.bcrypt:(trapped) error reading bcrypt version
Traceback (most recent call last):
  File "C:\Users\hugogarsan\AppData\Local\Packages\PythonSoftwareFoundation.Python.3.11_qbz5n2kfra8p0\LocalCache\local-packages\Python311\site-packages\passlib\handlers\bcrypt.py", line 620, in _load_backend_mixin
    version = _bcrypt.__about__.__version__
              ^^^^^^^^^^^^^^^^^
AttributeError: module 'bcrypt' has no attribute '__about__'
WARNING:passlib.handlers.bcrypt:(trapped) error reading bcrypt version
Traceback (most recent call last):
  File "C:\Users\hugogarsan\AppData\Local\Packages\PythonSoftwareFoundation.Python.3.11_qbz5n2kfra8p0\LocalCache\local-packages\Python311\site-packages\passlib\handlers\bcrypt.py", line 620, in _load_backend_mixin
    version = _bcrypt.__about__.__version__
              ^^^^^^^^^^^^^^^^^
AttributeError: module 'bcrypt' has no attribute '__about__'
INFO:paramiko.transport:Connected (version 2.0, client OpenSSH_8.2p1)
INFO:paramiko.transport:Authentication (publickey) failed.
INFO:paramiko.transport:Connected (version 2.0, client OpenSSH_8.2p1)
INFO:paramiko.transport:Authentication (publickey) failed.
INFO:paramiko.transport:Authentication (password) successful!
INFO:paramiko.transport:Connected (version 2.0, client OpenSSH_8.2p1)
INFO:paramiko.transport:Authentication (publickey) failed.
INFO:paramiko.transport:Authentication (password) successful!
INFO:paramiko.transport:Connected (version 2.0, client OpenSSH_8.2p1)
INFO:paramiko.transport:Authentication (publickey) failed.
INFO:paramiko.transport:Authentication (password) successful!
INFO:paramiko.transport:Connected (version 2.0, client OpenSSH_8.2p1)
INFO:paramiko.transport:Authentication (publickey) failed.
INFO:paramiko.transport:Authentication (password) successful!
INFO:paramiko.transport:Connected (version 2.0, client OpenSSH_8.2p1)
INFO:paramiko.transport:Authentication (publickey) failed.
INFO:paramiko.transport:Authentication (password) successful!
INFO:paramiko.transport:Connected (version 2.0, client OpenSSH_8.2p1)
INFO:paramiko.transport:Authentication (publickey) failed.
INFO:paramiko.transport:Authentication (password) successful!
INFO:paramiko.transport:Connected (version 2.0, client OpenSSH_8.2p1)
INFO:paramiko.transport:Authentication (publickey) failed.
INFO:paramiko.transport:Authentication (password) successful!
WARNING:passlib.handlers.bcrypt:(trapped) error reading bcrypt version
Traceback (most recent call last):
  File "C:\Users\hugogarsan\AppData\Local\Packages\PythonSoftwareFoundation.Python.3.11_qbz5n2kfra8p0\LocalCache\local-packages\Python311\site-packages\passlib\handlers\bcrypt.py", line 620, in _load_backend_mixin
    version = _bcrypt.__about__.__version__
              ^^^^^^^^^^^^^^^^^
AttributeError: module 'bcrypt' has no attribute '__about__'
INFO:paramiko.transport:Connected (version 2.0, client OpenSSH_8.2p1)
INFO:paramiko.transport:Authentication (publickey) failed.
INFO:paramiko.transport:Authentication (password) successful!
INFO:paramiko.transport:Connected (version 2.0, client OpenSSH_8.2p1)
INFO:paramiko.transport:Authentication (publickey) failed.
INFO:paramiko.transport:Authentication (password) successful!
INFO:paramiko.transport:Connected (version 2.0, client OpenSSH_8.2p1)
INFO:paramiko.transport:Authentication (publickey) failed.
INFO:paramiko.transport:Authentication (password) successful!
INFO:paramiko.transport:Connected (version 2.0, client OpenSSH_8.2p1)
INFO:paramiko.transport:Authentication (publickey) failed.
INFO:paramiko.transport:Authentication (password) successful!
WARNING:passlib.handlers.bcrypt:(trapped) error reading bcrypt version
Traceback (most recent call last):
  File "C:\Users\hugogarsan\AppData\Local\Packages\PythonSoftwareFoundation.Python.3.11_qbz5n2kfra8p0\LocalCache\local-packages\Python311\site-packages\passlib\handlers\bcrypt.py", line 620, in _load_backend_mixin
    version = _bcrypt.__about__.__version__
              ^^^^^^^^^^^^^^^^^
AttributeError: module 'bcrypt' has no attribute '__about__'
INFO:paramiko.transport:Connected (version 2.0, client OpenSSH_8.2p1)
INFO:paramiko.transport:Authentication (publickey) failed.
INFO:paramiko.transport:Authentication (password) successful!
WARNING:passlib.handlers.bcrypt:(trapped) error reading bcrypt version
Traceback (most recent call last):
  File "C:\Users\hugogarsan\AppData\Local\Packages\PythonSoftwareFoundation.Python.3.11_qbz5n2kfra8p0\LocalCache\local-packages\Python311\site-packages\passlib\handlers\bcrypt.py", line 620, in _load_backend_mixin
    version = _bcrypt.__about__.__version__
              ^^^^^^^^^^^^^^^^^
AttributeError: module 'bcrypt' has no attribute '__about__'
INFO:paramiko.transport:Connected (version 2.0, client OpenSSH_8.2p1)
INFO:paramiko.transport:Authentication (publickey) failed.
INFO:paramiko.transport:Authentication (password) successful!
ERROR:paramiko.transport:Exception: Error reading SSH protocol banner
ERROR:paramiko.transport:Traceback (most recent call last):
ERROR:paramiko.transport:  File "E:\Project\Back\.venv\Lib\site-packages\paramiko\transport.py", line 2211, in _check_banner
ERROR:paramiko.transport:    buf = self.packetizer.readline(timeout)
ERROR:paramiko.transport:          ^^^^^^^^^^^^^^^^^^^^^^^^^^^^^^^^^
ERROR:paramiko.transport:  File "E:\Project\Back\.venv\Lib\site-packages\paramiko\packet.py", line 380, in readline
ERROR:paramiko.transport:    buf += self._read_timeout(timeout)
ERROR:paramiko.transport:           ^^^^^^^^^^^^^^^^^^^^^^^^^^^
ERROR:paramiko.transport:  File "E:\Project\Back\.venv\Lib\site-packages\paramiko\packet.py", line 622, in _read_timeout
ERROR:paramiko.transport:    raise socket.timeout()
ERROR:paramiko.transport:TimeoutError
ERROR:paramiko.transport:
ERROR:paramiko.transport:During handling of the above exception, another exception occurred:
ERROR:paramiko.transport:
ERROR:paramiko.transport:Traceback (most recent call last):
ERROR:paramiko.transport:  File "E:\Project\Back\.venv\Lib\site-packages\paramiko\transport.py", line 2039, in run
ERROR:paramiko.transport:    self._check_banner()
ERROR:paramiko.transport:  File "E:\Project\Back\.venv\Lib\site-packages\paramiko\transport.py", line 2215, in _check_banner
ERROR:paramiko.transport:    raise SSHException(
ERROR:paramiko.transport:paramiko.ssh_exception.SSHException: Error reading SSH protocol banner
ERROR:paramiko.transport:
INFO:root:2024-04-22 17:40:22.429288 - Login attempt for username: string
INFO:root:2024-04-22 17:40:33.724931 - Login successful for username: string
ERROR:paramiko.transport:Exception: Error reading SSH protocol banner
ERROR:paramiko.transport:Traceback (most recent call last):
ERROR:paramiko.transport:  File "E:\Project\Back\.venv\Lib\site-packages\paramiko\transport.py", line 2211, in _check_banner
ERROR:paramiko.transport:    buf = self.packetizer.readline(timeout)
ERROR:paramiko.transport:          ^^^^^^^^^^^^^^^^^^^^^^^^^^^^^^^^^
ERROR:paramiko.transport:  File "E:\Project\Back\.venv\Lib\site-packages\paramiko\packet.py", line 380, in readline
ERROR:paramiko.transport:    buf += self._read_timeout(timeout)
ERROR:paramiko.transport:           ^^^^^^^^^^^^^^^^^^^^^^^^^^^
ERROR:paramiko.transport:  File "E:\Project\Back\.venv\Lib\site-packages\paramiko\packet.py", line 622, in _read_timeout
ERROR:paramiko.transport:    raise socket.timeout()
ERROR:paramiko.transport:TimeoutError
ERROR:paramiko.transport:
ERROR:paramiko.transport:During handling of the above exception, another exception occurred:
ERROR:paramiko.transport:
ERROR:paramiko.transport:Traceback (most recent call last):
ERROR:paramiko.transport:  File "E:\Project\Back\.venv\Lib\site-packages\paramiko\transport.py", line 2039, in run
ERROR:paramiko.transport:    self._check_banner()
ERROR:paramiko.transport:  File "E:\Project\Back\.venv\Lib\site-packages\paramiko\transport.py", line 2215, in _check_banner
ERROR:paramiko.transport:    raise SSHException(
ERROR:paramiko.transport:paramiko.ssh_exception.SSHException: Error reading SSH protocol banner
ERROR:paramiko.transport:
INFO:root:2024-04-22 18:28:09.764430 - Login attempt for username: string
INFO:root:2024-04-22 18:28:21.175193 - Login successful for username: string
INFO:root:2024-04-22 18:30:08.677397 - Login successful for username: string
INFO:paramiko.transport:Connected (version 2.0, client OpenSSH_8.2p1)
INFO:paramiko.transport:Authentication (password) successful!
INFO:root:2024-04-22 18:33:48.519507 - Login successful for username: string
INFO:root:2024-04-22 18:36:21.810587 - Login successful for username: string
INFO:root:2024-04-22 18:59:21.874459 - Login successful for username: string
INFO:root:2024-04-22 19:05:48.116274 - Login failed - Incorrect username: Hugo123
INFO:root:2024-04-22 19:05:50.535512 - Login failed - Incorrect username: Hugo123
INFO:paramiko.transport:Connected (version 2.0, client OpenSSH_8.2p1)
INFO:paramiko.transport:Authentication (password) successful!
INFO:root:2024-04-22 19:08:57.535571 - Login successful for username: string
INFO:root:2024-04-22 19:14:55.152667 - Login successful for username: string
INFO:root:2024-04-22 19:14:55.609660 - Login successful for username: string
INFO:root:2024-04-22 19:14:55.995477 - Login successful for username: string
ERROR:asyncio:Future exception was never retrieved
future: <Future finished exception=InvalidDocument("cannot encode object: User(name='string', last_name='string', age=0, username='string', email='string', password='$2b$12$h4DKuYsETp8Mt/mnuhUOYOfhvFxOY4u6NNS5M55nB66uEVXDaKTIy', disabled=False), of type: <class 'model.shemas.User'>")>
Traceback (most recent call last):
  File "C:\Users\martimasxax\AppData\Local\Programs\Python\Python312\Lib\concurrent\futures\thread.py", line 58, in run
    result = self.fn(*self.args, **self.kwargs)
             ^^^^^^^^^^^^^^^^^^^^^^^^^^^^^^^^^^
  File "E:\Project\Back\.venv\Lib\site-packages\pymongo\collection.py", line 1506, in find_one
    for result in cursor.limit(-1):
  File "E:\Project\Back\.venv\Lib\site-packages\pymongo\cursor.py", line 1264, in next
    if len(self.__data) or self._refresh():
                           ^^^^^^^^^^^^^^^
  File "E:\Project\Back\.venv\Lib\site-packages\pymongo\cursor.py", line 1181, in _refresh
    self.__send_message(q)
  File "E:\Project\Back\.venv\Lib\site-packages\pymongo\cursor.py", line 1060, in __send_message
    response = client._run_operation(
               ^^^^^^^^^^^^^^^^^^^^^^
  File "E:\Project\Back\.venv\Lib\site-packages\pymongo\_csot.py", line 107, in csot_wrapper
    return func(self, *args, **kwargs)
           ^^^^^^^^^^^^^^^^^^^^^^^^^^^
  File "E:\Project\Back\.venv\Lib\site-packages\pymongo\mongo_client.py", line 1394, in _run_operation
    return self._retryable_read(
           ^^^^^^^^^^^^^^^^^^^^^
  File "E:\Project\Back\.venv\Lib\site-packages\pymongo\mongo_client.py", line 1492, in _retryable_read
    return self._retry_internal(
           ^^^^^^^^^^^^^^^^^^^^^
  File "E:\Project\Back\.venv\Lib\site-packages\pymongo\_csot.py", line 107, in csot_wrapper
    return func(self, *args, **kwargs)
           ^^^^^^^^^^^^^^^^^^^^^^^^^^^
  File "E:\Project\Back\.venv\Lib\site-packages\pymongo\mongo_client.py", line 1462, in _retry_internal
    ).run()
      ^^^^^
  File "E:\Project\Back\.venv\Lib\site-packages\pymongo\mongo_client.py", line 2315, in run
    return self._read() if self._is_read else self._write()
           ^^^^^^^^^^^^
  File "E:\Project\Back\.venv\Lib\site-packages\pymongo\mongo_client.py", line 2445, in _read
    return self._func(self._session, self._server, conn, read_pref)  # type: ignore
           ^^^^^^^^^^^^^^^^^^^^^^^^^^^^^^^^^^^^^^^^^^^^^^^^^^^^^^^^
  File "E:\Project\Back\.venv\Lib\site-packages\pymongo\mongo_client.py", line 1390, in _cmd
    return server.run_operation(
           ^^^^^^^^^^^^^^^^^^^^^
  File "E:\Project\Back\.venv\Lib\site-packages\pymongo\helpers.py", line 322, in inner
    return func(*args, **kwargs)
           ^^^^^^^^^^^^^^^^^^^^^
  File "E:\Project\Back\.venv\Lib\site-packages\pymongo\server.py", line 130, in run_operation
    message = operation.get_message(read_preference, conn, use_cmd)
              ^^^^^^^^^^^^^^^^^^^^^^^^^^^^^^^^^^^^^^^^^^^^^^^^^^^^^
  File "E:\Project\Back\.venv\Lib\site-packages\pymongo\message.py", line 426, in get_message
    request_id, msg, size, _ = _op_msg(
                               ^^^^^^^^
  File "E:\Project\Back\.venv\Lib\site-packages\pymongo\message.py", line 762, in _op_msg
    return _op_msg_uncompressed(flags, command, identifier, docs, opts)
           ^^^^^^^^^^^^^^^^^^^^^^^^^^^^^^^^^^^^^^^^^^^^^^^^^^^^^^^^^^^^
bson.errors.InvalidDocument: cannot encode object: User(name='string', last_name='string', age=0, username='string', email='string', password='$2b$12$h4DKuYsETp8Mt/mnuhUOYOfhvFxOY4u6NNS5M55nB66uEVXDaKTIy', disabled=False), of type: <class 'model.shemas.User'>
INFO:root:2024-04-22 19:19:00.398643 - Login successful for username: string
ERROR:asyncio:Future exception was never retrieved
future: <Future finished exception=InvalidDocument("cannot encode object: User(name='string', last_name='string', age=0, username='string', email='string', password='$2b$12$h4DKuYsETp8Mt/mnuhUOYOfhvFxOY4u6NNS5M55nB66uEVXDaKTIy', disabled=False), of type: <class 'model.shemas.User'>")>
Traceback (most recent call last):
  File "C:\Users\martimasxax\AppData\Local\Programs\Python\Python312\Lib\concurrent\futures\thread.py", line 58, in run
    result = self.fn(*self.args, **self.kwargs)
             ^^^^^^^^^^^^^^^^^^^^^^^^^^^^^^^^^^
  File "E:\Project\Back\.venv\Lib\site-packages\pymongo\collection.py", line 1506, in find_one
    for result in cursor.limit(-1):
  File "E:\Project\Back\.venv\Lib\site-packages\pymongo\cursor.py", line 1264, in next
    if len(self.__data) or self._refresh():
                           ^^^^^^^^^^^^^^^
  File "E:\Project\Back\.venv\Lib\site-packages\pymongo\cursor.py", line 1181, in _refresh
    self.__send_message(q)
  File "E:\Project\Back\.venv\Lib\site-packages\pymongo\cursor.py", line 1060, in __send_message
    response = client._run_operation(
               ^^^^^^^^^^^^^^^^^^^^^^
  File "E:\Project\Back\.venv\Lib\site-packages\pymongo\_csot.py", line 107, in csot_wrapper
    return func(self, *args, **kwargs)
           ^^^^^^^^^^^^^^^^^^^^^^^^^^^
  File "E:\Project\Back\.venv\Lib\site-packages\pymongo\mongo_client.py", line 1394, in _run_operation
    return self._retryable_read(
           ^^^^^^^^^^^^^^^^^^^^^
  File "E:\Project\Back\.venv\Lib\site-packages\pymongo\mongo_client.py", line 1492, in _retryable_read
    return self._retry_internal(
           ^^^^^^^^^^^^^^^^^^^^^
  File "E:\Project\Back\.venv\Lib\site-packages\pymongo\_csot.py", line 107, in csot_wrapper
    return func(self, *args, **kwargs)
           ^^^^^^^^^^^^^^^^^^^^^^^^^^^
  File "E:\Project\Back\.venv\Lib\site-packages\pymongo\mongo_client.py", line 1462, in _retry_internal
    ).run()
      ^^^^^
  File "E:\Project\Back\.venv\Lib\site-packages\pymongo\mongo_client.py", line 2315, in run
    return self._read() if self._is_read else self._write()
           ^^^^^^^^^^^^
  File "E:\Project\Back\.venv\Lib\site-packages\pymongo\mongo_client.py", line 2445, in _read
    return self._func(self._session, self._server, conn, read_pref)  # type: ignore
           ^^^^^^^^^^^^^^^^^^^^^^^^^^^^^^^^^^^^^^^^^^^^^^^^^^^^^^^^
  File "E:\Project\Back\.venv\Lib\site-packages\pymongo\mongo_client.py", line 1390, in _cmd
    return server.run_operation(
           ^^^^^^^^^^^^^^^^^^^^^
  File "E:\Project\Back\.venv\Lib\site-packages\pymongo\helpers.py", line 322, in inner
    return func(*args, **kwargs)
           ^^^^^^^^^^^^^^^^^^^^^
  File "E:\Project\Back\.venv\Lib\site-packages\pymongo\server.py", line 130, in run_operation
    message = operation.get_message(read_preference, conn, use_cmd)
              ^^^^^^^^^^^^^^^^^^^^^^^^^^^^^^^^^^^^^^^^^^^^^^^^^^^^^
  File "E:\Project\Back\.venv\Lib\site-packages\pymongo\message.py", line 426, in get_message
    request_id, msg, size, _ = _op_msg(
                               ^^^^^^^^
  File "E:\Project\Back\.venv\Lib\site-packages\pymongo\message.py", line 762, in _op_msg
    return _op_msg_uncompressed(flags, command, identifier, docs, opts)
           ^^^^^^^^^^^^^^^^^^^^^^^^^^^^^^^^^^^^^^^^^^^^^^^^^^^^^^^^^^^^
bson.errors.InvalidDocument: cannot encode object: User(name='string', last_name='string', age=0, username='string', email='string', password='$2b$12$h4DKuYsETp8Mt/mnuhUOYOfhvFxOY4u6NNS5M55nB66uEVXDaKTIy', disabled=False), of type: <class 'model.shemas.User'>
INFO:root:2024-04-22 19:21:54.473201 - Login successful for username: string
INFO:root:2024-04-22 19:28:54.837705 - Login successful for username: string
INFO:root:2024-04-22 19:35:36.752128 - Login successful for username: string
INFO:root:2024-04-22 19:39:48.936000 - Login successful for username: string
ERROR:asyncio:Future exception was never retrieved
future: <Future finished exception=InvalidDocument("cannot encode object: UserInDB(name='string', last_name='string', age=0, username='string', email='string', password='$2b$12$h4DKuYsETp8Mt/mnuhUOYOfhvFxOY4u6NNS5M55nB66uEVXDaKTIy', disabled=False, id=None), of type: <class 'model.shemas.UserInDB'>")>
Traceback (most recent call last):
  File "C:\Users\martimasxax\AppData\Local\Programs\Python\Python312\Lib\concurrent\futures\thread.py", line 58, in run
    result = self.fn(*self.args, **self.kwargs)
             ^^^^^^^^^^^^^^^^^^^^^^^^^^^^^^^^^^
  File "E:\Project\Back\.venv\Lib\site-packages\pymongo\collection.py", line 1506, in find_one
    for result in cursor.limit(-1):
  File "E:\Project\Back\.venv\Lib\site-packages\pymongo\cursor.py", line 1264, in next
    if len(self.__data) or self._refresh():
                           ^^^^^^^^^^^^^^^
  File "E:\Project\Back\.venv\Lib\site-packages\pymongo\cursor.py", line 1181, in _refresh
    self.__send_message(q)
  File "E:\Project\Back\.venv\Lib\site-packages\pymongo\cursor.py", line 1060, in __send_message
    response = client._run_operation(
               ^^^^^^^^^^^^^^^^^^^^^^
  File "E:\Project\Back\.venv\Lib\site-packages\pymongo\_csot.py", line 107, in csot_wrapper
    return func(self, *args, **kwargs)
           ^^^^^^^^^^^^^^^^^^^^^^^^^^^
  File "E:\Project\Back\.venv\Lib\site-packages\pymongo\mongo_client.py", line 1394, in _run_operation
    return self._retryable_read(
           ^^^^^^^^^^^^^^^^^^^^^
  File "E:\Project\Back\.venv\Lib\site-packages\pymongo\mongo_client.py", line 1492, in _retryable_read
    return self._retry_internal(
           ^^^^^^^^^^^^^^^^^^^^^
  File "E:\Project\Back\.venv\Lib\site-packages\pymongo\_csot.py", line 107, in csot_wrapper
    return func(self, *args, **kwargs)
           ^^^^^^^^^^^^^^^^^^^^^^^^^^^
  File "E:\Project\Back\.venv\Lib\site-packages\pymongo\mongo_client.py", line 1462, in _retry_internal
    ).run()
      ^^^^^
  File "E:\Project\Back\.venv\Lib\site-packages\pymongo\mongo_client.py", line 2315, in run
    return self._read() if self._is_read else self._write()
           ^^^^^^^^^^^^
  File "E:\Project\Back\.venv\Lib\site-packages\pymongo\mongo_client.py", line 2445, in _read
    return self._func(self._session, self._server, conn, read_pref)  # type: ignore
           ^^^^^^^^^^^^^^^^^^^^^^^^^^^^^^^^^^^^^^^^^^^^^^^^^^^^^^^^
  File "E:\Project\Back\.venv\Lib\site-packages\pymongo\mongo_client.py", line 1390, in _cmd
    return server.run_operation(
           ^^^^^^^^^^^^^^^^^^^^^
  File "E:\Project\Back\.venv\Lib\site-packages\pymongo\helpers.py", line 322, in inner
    return func(*args, **kwargs)
           ^^^^^^^^^^^^^^^^^^^^^
  File "E:\Project\Back\.venv\Lib\site-packages\pymongo\server.py", line 130, in run_operation
    message = operation.get_message(read_preference, conn, use_cmd)
              ^^^^^^^^^^^^^^^^^^^^^^^^^^^^^^^^^^^^^^^^^^^^^^^^^^^^^
  File "E:\Project\Back\.venv\Lib\site-packages\pymongo\message.py", line 426, in get_message
    request_id, msg, size, _ = _op_msg(
                               ^^^^^^^^
  File "E:\Project\Back\.venv\Lib\site-packages\pymongo\message.py", line 762, in _op_msg
    return _op_msg_uncompressed(flags, command, identifier, docs, opts)
           ^^^^^^^^^^^^^^^^^^^^^^^^^^^^^^^^^^^^^^^^^^^^^^^^^^^^^^^^^^^^
bson.errors.InvalidDocument: cannot encode object: UserInDB(name='string', last_name='string', age=0, username='string', email='string', password='$2b$12$h4DKuYsETp8Mt/mnuhUOYOfhvFxOY4u6NNS5M55nB66uEVXDaKTIy', disabled=False, id=None), of type: <class 'model.shemas.UserInDB'>
INFO:root:2024-04-22 19:43:13.435359 - Login successful for username: string
ERROR:asyncio:Future exception was never retrieved
future: <Future finished exception=InvalidDocument("cannot encode object: UserInDB(name='string', last_name='string', age=0, username='string', email='string', password='$2b$12$h4DKuYsETp8Mt/mnuhUOYOfhvFxOY4u6NNS5M55nB66uEVXDaKTIy', disabled=False, id=None), of type: <class 'model.shemas.UserInDB'>")>
Traceback (most recent call last):
  File "C:\Users\martimasxax\AppData\Local\Programs\Python\Python312\Lib\concurrent\futures\thread.py", line 58, in run
    result = self.fn(*self.args, **self.kwargs)
             ^^^^^^^^^^^^^^^^^^^^^^^^^^^^^^^^^^
  File "E:\Project\Back\.venv\Lib\site-packages\pymongo\collection.py", line 1506, in find_one
    for result in cursor.limit(-1):
  File "E:\Project\Back\.venv\Lib\site-packages\pymongo\cursor.py", line 1264, in next
    if len(self.__data) or self._refresh():
                           ^^^^^^^^^^^^^^^
  File "E:\Project\Back\.venv\Lib\site-packages\pymongo\cursor.py", line 1181, in _refresh
    self.__send_message(q)
  File "E:\Project\Back\.venv\Lib\site-packages\pymongo\cursor.py", line 1060, in __send_message
    response = client._run_operation(
               ^^^^^^^^^^^^^^^^^^^^^^
  File "E:\Project\Back\.venv\Lib\site-packages\pymongo\_csot.py", line 107, in csot_wrapper
    return func(self, *args, **kwargs)
           ^^^^^^^^^^^^^^^^^^^^^^^^^^^
  File "E:\Project\Back\.venv\Lib\site-packages\pymongo\mongo_client.py", line 1394, in _run_operation
    return self._retryable_read(
           ^^^^^^^^^^^^^^^^^^^^^
  File "E:\Project\Back\.venv\Lib\site-packages\pymongo\mongo_client.py", line 1492, in _retryable_read
    return self._retry_internal(
           ^^^^^^^^^^^^^^^^^^^^^
  File "E:\Project\Back\.venv\Lib\site-packages\pymongo\_csot.py", line 107, in csot_wrapper
    return func(self, *args, **kwargs)
           ^^^^^^^^^^^^^^^^^^^^^^^^^^^
  File "E:\Project\Back\.venv\Lib\site-packages\pymongo\mongo_client.py", line 1462, in _retry_internal
    ).run()
      ^^^^^
  File "E:\Project\Back\.venv\Lib\site-packages\pymongo\mongo_client.py", line 2315, in run
    return self._read() if self._is_read else self._write()
           ^^^^^^^^^^^^
  File "E:\Project\Back\.venv\Lib\site-packages\pymongo\mongo_client.py", line 2445, in _read
    return self._func(self._session, self._server, conn, read_pref)  # type: ignore
           ^^^^^^^^^^^^^^^^^^^^^^^^^^^^^^^^^^^^^^^^^^^^^^^^^^^^^^^^
  File "E:\Project\Back\.venv\Lib\site-packages\pymongo\mongo_client.py", line 1390, in _cmd
    return server.run_operation(
           ^^^^^^^^^^^^^^^^^^^^^
  File "E:\Project\Back\.venv\Lib\site-packages\pymongo\helpers.py", line 322, in inner
    return func(*args, **kwargs)
           ^^^^^^^^^^^^^^^^^^^^^
  File "E:\Project\Back\.venv\Lib\site-packages\pymongo\server.py", line 130, in run_operation
    message = operation.get_message(read_preference, conn, use_cmd)
              ^^^^^^^^^^^^^^^^^^^^^^^^^^^^^^^^^^^^^^^^^^^^^^^^^^^^^
  File "E:\Project\Back\.venv\Lib\site-packages\pymongo\message.py", line 426, in get_message
    request_id, msg, size, _ = _op_msg(
                               ^^^^^^^^
  File "E:\Project\Back\.venv\Lib\site-packages\pymongo\message.py", line 762, in _op_msg
    return _op_msg_uncompressed(flags, command, identifier, docs, opts)
           ^^^^^^^^^^^^^^^^^^^^^^^^^^^^^^^^^^^^^^^^^^^^^^^^^^^^^^^^^^^^
bson.errors.InvalidDocument: cannot encode object: UserInDB(name='string', last_name='string', age=0, username='string', email='string', password='$2b$12$h4DKuYsETp8Mt/mnuhUOYOfhvFxOY4u6NNS5M55nB66uEVXDaKTIy', disabled=False, id=None), of type: <class 'model.shemas.UserInDB'>
INFO:root:2024-04-22 19:45:44.897851 - Login successful for username: string
ERROR:asyncio:Future exception was never retrieved
future: <Future finished exception=InvalidDocument("cannot encode object: UserInDB(name='string', last_name='string', age=0, username='string', email='string', password='$2b$12$h4DKuYsETp8Mt/mnuhUOYOfhvFxOY4u6NNS5M55nB66uEVXDaKTIy', disabled=False, id=None), of type: <class 'model.shemas.UserInDB'>")>
Traceback (most recent call last):
  File "C:\Users\martimasxax\AppData\Local\Programs\Python\Python312\Lib\concurrent\futures\thread.py", line 58, in run
    result = self.fn(*self.args, **self.kwargs)
             ^^^^^^^^^^^^^^^^^^^^^^^^^^^^^^^^^^
  File "E:\Project\Back\.venv\Lib\site-packages\pymongo\collection.py", line 1506, in find_one
    for result in cursor.limit(-1):
  File "E:\Project\Back\.venv\Lib\site-packages\pymongo\cursor.py", line 1264, in next
    if len(self.__data) or self._refresh():
                           ^^^^^^^^^^^^^^^
  File "E:\Project\Back\.venv\Lib\site-packages\pymongo\cursor.py", line 1181, in _refresh
    self.__send_message(q)
  File "E:\Project\Back\.venv\Lib\site-packages\pymongo\cursor.py", line 1060, in __send_message
    response = client._run_operation(
               ^^^^^^^^^^^^^^^^^^^^^^
  File "E:\Project\Back\.venv\Lib\site-packages\pymongo\_csot.py", line 107, in csot_wrapper
    return func(self, *args, **kwargs)
           ^^^^^^^^^^^^^^^^^^^^^^^^^^^
  File "E:\Project\Back\.venv\Lib\site-packages\pymongo\mongo_client.py", line 1394, in _run_operation
    return self._retryable_read(
           ^^^^^^^^^^^^^^^^^^^^^
  File "E:\Project\Back\.venv\Lib\site-packages\pymongo\mongo_client.py", line 1492, in _retryable_read
    return self._retry_internal(
           ^^^^^^^^^^^^^^^^^^^^^
  File "E:\Project\Back\.venv\Lib\site-packages\pymongo\_csot.py", line 107, in csot_wrapper
    return func(self, *args, **kwargs)
           ^^^^^^^^^^^^^^^^^^^^^^^^^^^
  File "E:\Project\Back\.venv\Lib\site-packages\pymongo\mongo_client.py", line 1462, in _retry_internal
    ).run()
      ^^^^^
  File "E:\Project\Back\.venv\Lib\site-packages\pymongo\mongo_client.py", line 2315, in run
    return self._read() if self._is_read else self._write()
           ^^^^^^^^^^^^
  File "E:\Project\Back\.venv\Lib\site-packages\pymongo\mongo_client.py", line 2445, in _read
    return self._func(self._session, self._server, conn, read_pref)  # type: ignore
           ^^^^^^^^^^^^^^^^^^^^^^^^^^^^^^^^^^^^^^^^^^^^^^^^^^^^^^^^
  File "E:\Project\Back\.venv\Lib\site-packages\pymongo\mongo_client.py", line 1390, in _cmd
    return server.run_operation(
           ^^^^^^^^^^^^^^^^^^^^^
  File "E:\Project\Back\.venv\Lib\site-packages\pymongo\helpers.py", line 322, in inner
    return func(*args, **kwargs)
           ^^^^^^^^^^^^^^^^^^^^^
  File "E:\Project\Back\.venv\Lib\site-packages\pymongo\server.py", line 130, in run_operation
    message = operation.get_message(read_preference, conn, use_cmd)
              ^^^^^^^^^^^^^^^^^^^^^^^^^^^^^^^^^^^^^^^^^^^^^^^^^^^^^
  File "E:\Project\Back\.venv\Lib\site-packages\pymongo\message.py", line 426, in get_message
    request_id, msg, size, _ = _op_msg(
                               ^^^^^^^^
  File "E:\Project\Back\.venv\Lib\site-packages\pymongo\message.py", line 762, in _op_msg
    return _op_msg_uncompressed(flags, command, identifier, docs, opts)
           ^^^^^^^^^^^^^^^^^^^^^^^^^^^^^^^^^^^^^^^^^^^^^^^^^^^^^^^^^^^^
bson.errors.InvalidDocument: cannot encode object: UserInDB(name='string', last_name='string', age=0, username='string', email='string', password='$2b$12$h4DKuYsETp8Mt/mnuhUOYOfhvFxOY4u6NNS5M55nB66uEVXDaKTIy', disabled=False, id=None), of type: <class 'model.shemas.UserInDB'>
INFO:root:2024-04-23 15:26:18.002303 - Login successful for username: string
INFO:root:2024-04-23 15:26:18.288810 - Login successful for username: string
ERROR:asyncio:Future exception was never retrieved
future: <Future finished exception=InvalidDocument("cannot encode object: User(name='string', last_name='string', age=0, username='string', email='string', password='$2b$12$h4DKuYsETp8Mt/mnuhUOYOfhvFxOY4u6NNS5M55nB66uEVXDaKTIy', disabled=False), of type: <class 'model.shemas.User'>")>
Traceback (most recent call last):
  File "C:\Users\martimasxax\AppData\Local\Programs\Python\Python312\Lib\concurrent\futures\thread.py", line 58, in run
    result = self.fn(*self.args, **self.kwargs)
             ^^^^^^^^^^^^^^^^^^^^^^^^^^^^^^^^^^
  File "E:\Project\Back\.venv\Lib\site-packages\pymongo\collection.py", line 1506, in find_one
    for result in cursor.limit(-1):
  File "E:\Project\Back\.venv\Lib\site-packages\pymongo\cursor.py", line 1264, in next
    if len(self.__data) or self._refresh():
                           ^^^^^^^^^^^^^^^
  File "E:\Project\Back\.venv\Lib\site-packages\pymongo\cursor.py", line 1181, in _refresh
    self.__send_message(q)
  File "E:\Project\Back\.venv\Lib\site-packages\pymongo\cursor.py", line 1060, in __send_message
    response = client._run_operation(
               ^^^^^^^^^^^^^^^^^^^^^^
  File "E:\Project\Back\.venv\Lib\site-packages\pymongo\_csot.py", line 107, in csot_wrapper
    return func(self, *args, **kwargs)
           ^^^^^^^^^^^^^^^^^^^^^^^^^^^
  File "E:\Project\Back\.venv\Lib\site-packages\pymongo\mongo_client.py", line 1394, in _run_operation
    return self._retryable_read(
           ^^^^^^^^^^^^^^^^^^^^^
  File "E:\Project\Back\.venv\Lib\site-packages\pymongo\mongo_client.py", line 1492, in _retryable_read
    return self._retry_internal(
           ^^^^^^^^^^^^^^^^^^^^^
  File "E:\Project\Back\.venv\Lib\site-packages\pymongo\_csot.py", line 107, in csot_wrapper
    return func(self, *args, **kwargs)
           ^^^^^^^^^^^^^^^^^^^^^^^^^^^
  File "E:\Project\Back\.venv\Lib\site-packages\pymongo\mongo_client.py", line 1462, in _retry_internal
    ).run()
      ^^^^^
  File "E:\Project\Back\.venv\Lib\site-packages\pymongo\mongo_client.py", line 2315, in run
    return self._read() if self._is_read else self._write()
           ^^^^^^^^^^^^
  File "E:\Project\Back\.venv\Lib\site-packages\pymongo\mongo_client.py", line 2445, in _read
    return self._func(self._session, self._server, conn, read_pref)  # type: ignore
           ^^^^^^^^^^^^^^^^^^^^^^^^^^^^^^^^^^^^^^^^^^^^^^^^^^^^^^^^
  File "E:\Project\Back\.venv\Lib\site-packages\pymongo\mongo_client.py", line 1390, in _cmd
    return server.run_operation(
           ^^^^^^^^^^^^^^^^^^^^^
  File "E:\Project\Back\.venv\Lib\site-packages\pymongo\helpers.py", line 322, in inner
    return func(*args, **kwargs)
           ^^^^^^^^^^^^^^^^^^^^^
  File "E:\Project\Back\.venv\Lib\site-packages\pymongo\server.py", line 130, in run_operation
    message = operation.get_message(read_preference, conn, use_cmd)
              ^^^^^^^^^^^^^^^^^^^^^^^^^^^^^^^^^^^^^^^^^^^^^^^^^^^^^
  File "E:\Project\Back\.venv\Lib\site-packages\pymongo\message.py", line 426, in get_message
    request_id, msg, size, _ = _op_msg(
                               ^^^^^^^^
  File "E:\Project\Back\.venv\Lib\site-packages\pymongo\message.py", line 762, in _op_msg
    return _op_msg_uncompressed(flags, command, identifier, docs, opts)
           ^^^^^^^^^^^^^^^^^^^^^^^^^^^^^^^^^^^^^^^^^^^^^^^^^^^^^^^^^^^^
bson.errors.InvalidDocument: cannot encode object: User(name='string', last_name='string', age=0, username='string', email='string', password='$2b$12$h4DKuYsETp8Mt/mnuhUOYOfhvFxOY4u6NNS5M55nB66uEVXDaKTIy', disabled=False), of type: <class 'model.shemas.User'>
INFO:root:2024-04-23 15:29:02.320701 - Login successful for username: string
INFO:root:2024-04-23 15:31:43.365105 - Login successful for username: string
ERROR:asyncio:Future exception was never retrieved
future: <Future finished exception=InvalidDocument("cannot encode object: User(name='string', last_name='string', age=0, username='string', email='string', password='$2b$12$h4DKuYsETp8Mt/mnuhUOYOfhvFxOY4u6NNS5M55nB66uEVXDaKTIy', disabled=False), of type: <class 'model.shemas.User'>")>
Traceback (most recent call last):
  File "C:\Users\martimasxax\AppData\Local\Programs\Python\Python312\Lib\concurrent\futures\thread.py", line 58, in run
    result = self.fn(*self.args, **self.kwargs)
             ^^^^^^^^^^^^^^^^^^^^^^^^^^^^^^^^^^
  File "E:\Project\Back\.venv\Lib\site-packages\pymongo\collection.py", line 1506, in find_one
    for result in cursor.limit(-1):
  File "E:\Project\Back\.venv\Lib\site-packages\pymongo\cursor.py", line 1264, in next
    if len(self.__data) or self._refresh():
                           ^^^^^^^^^^^^^^^
  File "E:\Project\Back\.venv\Lib\site-packages\pymongo\cursor.py", line 1181, in _refresh
    self.__send_message(q)
  File "E:\Project\Back\.venv\Lib\site-packages\pymongo\cursor.py", line 1060, in __send_message
    response = client._run_operation(
               ^^^^^^^^^^^^^^^^^^^^^^
  File "E:\Project\Back\.venv\Lib\site-packages\pymongo\_csot.py", line 107, in csot_wrapper
    return func(self, *args, **kwargs)
           ^^^^^^^^^^^^^^^^^^^^^^^^^^^
  File "E:\Project\Back\.venv\Lib\site-packages\pymongo\mongo_client.py", line 1394, in _run_operation
    return self._retryable_read(
           ^^^^^^^^^^^^^^^^^^^^^
  File "E:\Project\Back\.venv\Lib\site-packages\pymongo\mongo_client.py", line 1492, in _retryable_read
    return self._retry_internal(
           ^^^^^^^^^^^^^^^^^^^^^
  File "E:\Project\Back\.venv\Lib\site-packages\pymongo\_csot.py", line 107, in csot_wrapper
    return func(self, *args, **kwargs)
           ^^^^^^^^^^^^^^^^^^^^^^^^^^^
  File "E:\Project\Back\.venv\Lib\site-packages\pymongo\mongo_client.py", line 1462, in _retry_internal
    ).run()
      ^^^^^
  File "E:\Project\Back\.venv\Lib\site-packages\pymongo\mongo_client.py", line 2315, in run
    return self._read() if self._is_read else self._write()
           ^^^^^^^^^^^^
  File "E:\Project\Back\.venv\Lib\site-packages\pymongo\mongo_client.py", line 2445, in _read
    return self._func(self._session, self._server, conn, read_pref)  # type: ignore
           ^^^^^^^^^^^^^^^^^^^^^^^^^^^^^^^^^^^^^^^^^^^^^^^^^^^^^^^^
  File "E:\Project\Back\.venv\Lib\site-packages\pymongo\mongo_client.py", line 1390, in _cmd
    return server.run_operation(
           ^^^^^^^^^^^^^^^^^^^^^
  File "E:\Project\Back\.venv\Lib\site-packages\pymongo\helpers.py", line 322, in inner
    return func(*args, **kwargs)
           ^^^^^^^^^^^^^^^^^^^^^
  File "E:\Project\Back\.venv\Lib\site-packages\pymongo\server.py", line 130, in run_operation
    message = operation.get_message(read_preference, conn, use_cmd)
              ^^^^^^^^^^^^^^^^^^^^^^^^^^^^^^^^^^^^^^^^^^^^^^^^^^^^^
  File "E:\Project\Back\.venv\Lib\site-packages\pymongo\message.py", line 426, in get_message
    request_id, msg, size, _ = _op_msg(
                               ^^^^^^^^
  File "E:\Project\Back\.venv\Lib\site-packages\pymongo\message.py", line 762, in _op_msg
    return _op_msg_uncompressed(flags, command, identifier, docs, opts)
           ^^^^^^^^^^^^^^^^^^^^^^^^^^^^^^^^^^^^^^^^^^^^^^^^^^^^^^^^^^^^
bson.errors.InvalidDocument: cannot encode object: User(name='string', last_name='string', age=0, username='string', email='string', password='$2b$12$h4DKuYsETp8Mt/mnuhUOYOfhvFxOY4u6NNS5M55nB66uEVXDaKTIy', disabled=False), of type: <class 'model.shemas.User'>
INFO:root:2024-04-23 15:33:44.295458 - Login successful for username: string
INFO:root:2024-04-23 15:36:23.754775 - Login successful for username: string
INFO:root:2024-04-23 15:41:51.176099 - Login successful for username: string
INFO:root:2024-04-23 15:45:13.625309 - Login successful for username: string
INFO:root:2024-04-23 15:47:23.472610 - Login successful for username: string
INFO:root:2024-04-23 15:47:23.985133 - Login successful for username: string
INFO:root:2024-04-23 15:48:57.191022 - Login successful for username: string
INFO:root:2024-04-23 15:52:19.301252 - Login successful for username: string
INFO:root:2024-04-23 15:59:20.740681 - Login successful for username: string
INFO:root:2024-04-23 15:59:20.996522 - Login successful for username: string
INFO:root:2024-04-23 16:03:34.173538 - Login successful for username: string
INFO:root:2024-04-23 16:03:34.408082 - Login successful for username: string
